Workbook

Sheet ALM 51
A1: Organization | B1: Item | C1: Subinventory | D1: Rev | E1: UOM | F1: Locator | G1: On-hand Qty | H1: Nettable | I1: Reservable | J1: ATP | K1: Organization Name | L1: Item Description | M1: Maximum Weight | N1: Maximum Unit | O1: Weight | P1: Volume | Q1: Maximum Volume | R1: Weight UOM | S1: Volume UOM | T1: Locator Description
A2: OSR | B2: M200295061 | C2: 71MG51ALM | D2: --- | E2: EA | F2: =VLOOKUP(B2,Planilha1!A:E,3,0) -> 2F-3C1 | G2: =VLOOKUP(B2,Planilha1!A:E,4,0) -> 190 | H2: * | I2: * | J2: * | K2: MERITOR BR - FABRICA OSASCO | L2: =VLOOKUP(B2,Planilha1!A:E,5,0) -> PASTILHA T490 LNMT 1306PNTR IC810. (PEDIDO EM ABERTO ISCAR). - LEAD TIME 14 DIAS
A3: OSR | B3: M124106030 | C3: 71MG51ALM | E3: EA | F3: =VLOOKUP(B3,Planilha1!A:E,3,0) -> 10A-7F1 | G3: =VLOOKUP(B3,Planilha1!A:E,4,0) -> 50 | H3: * | I3: * | J3: * | K3: MERITOR BR - FABRICA OSASCO | L3: =VLOOKUP(B3,Planilha1!A:E,5,0) -> PARAFUSO ALLEN C/CABECA CILINDRICA M- 6 X 1
A4: OSR | B4: M200295045 | C4: 71MG51ALM | E4: EA | F4: =VLOOKUP(B4,Planilha1!A:E,3,0) -> 8B-3E2 | G4: =VLOOKUP(B4,Planilha1!A:E,4,0) -> 60 | H4: * | I4: * | J4: * | K4: MERITOR BR - FABRICA OSASCO | L4: =VLOOKUP(B4,Planilha1!A:E,5,0) -> PASTILHA SDMT120408-D51 WKP25S 4 ARESTAS T406 HELLER 14000 - LEAD TIME 15 DIAS
A5: OSR | B5: M412000025 | C5: 71MG51ALM | E5: EA | F5: =VLOOKUP(B5,Planilha1!A:E,3,0) -> 5D-5F | G5: =VLOOKUP(B5,Planilha1!A:E,4,0) -> 90 | H5: * | I5: * | J5: * | K5: MERITOR BR - FABRICA OSASCO | L5: =VLOOKUP(B5,Planilha1!A:E,5,0) -> BICO DE CONTATO CUCRZR 1
A6: OSR | B6: M400000854 | C6: 71MG51ALM | E6: EA | F6: =VLOOKUP(B6,Planilha1!A:E,3,0) -> 19N-2 | G6: =VLOOKUP(B6,Planilha1!A:E,4,0) -> 10 | H6: * | I6: * | J6: * | K6: MERITOR BR - FABRICA OSASCO | L6: =VLOOKUP(B6,Planilha1!A:E,5,0) -> FILTRO PLISSADO PARA TINTA 800MM X 10M
A7: OSR | B7: M411000414 | C7: 71MG51ALM | E7: EA | F7: =VLOOKUP(B7,Planilha1!A:E,3,0) -> 5D-4A1 | G7: =VLOOKUP(B7,Planilha1!A:E,4,0) -> 31 | H7: * | I7: * | J7: * | K7: MERITOR BR - FABRICA OSASCO | L7: =VLOOKUP(B7,Planilha1!A:E,5,0) -> PONTEIRA ROBO DSR CONICA 18MM
A8: OSR | B8: M201000601 | C8: 71MG51ALM | E8: EA | F8: =VLOOKUP(B8,Planilha1!A:E,3,0) -> 6D-3C1 | G8: =VLOOKUP(B8,Planilha1!A:E,4,0) -> 470 | H8: * | I8: * | J8: * | K8: MERITOR BR - FABRICA OSASCO | L8: =VLOOKUP(B8,Planilha1!A:E,5,0) -> PASTILHA CNMM190616-HZ UH 6400. - I003252 - LEAD TIME 25 DIAS (PEDIDO EM ABERTO MITSUBISHI).
A9: OSR | B9: M899000156 | C9: 71MG51ALM | E9: EA | F9: =VLOOKUP(B9,Planilha1!A:E,3,0) -> #N/A | G9: =VLOOKUP(B9,Planilha1!A:E,4,0) -> #N/A | H9: * | I9: * | J9: * | K9: MERITOR BR - FABRICA OSASCO | L9: =VLOOKUP(B9,Planilha1!A:E,5,0) -> #N/A
A10: OSR | B10: M201000138 | C10: 71MG51ALM | E10: EA | F10: =VLOOKUP(B10,Planilha1!A:E,3,0) -> 6F-3B1 | G10: =VLOOKUP(B10,Planilha1!A:E,4,0) -> 340 | H10: * | I10: * | J10: * | K10: MERITOR BR - FABRICA OSASCO | L10: =VLOOKUP(B10,Planilha1!A:E,5,0) -> PASTILHA SNGX 12 05 ZNN-F57 WKK25. (PEDIDO EM ABERTO WALTER). (OBS. FUTURAMENTE SUBSTITUIRA A PASTILHA M201000143). - LEAD TIME 15 DIAS
A11: OSR | B11: M023230060 | C11: 71MG51ALM | E11: EA | F11: =VLOOKUP(B11,Planilha1!A:E,3,0) -> 11C-3B | G11: =VLOOKUP(B11,Planilha1!A:E,4,0) -> 1 | H11: * | I11: * | J11: * | K11: MERITOR BR - FABRICA OSASCO | L11: =VLOOKUP(B11,Planilha1!A:E,5,0) -> CORTADOR SHAVER DES. 23-0060. (PEDIDO EM ABERTO GLEASON).
A12: OSR | B12: M600005002 | C12: 71MG51ALM | E12: EA | F12: =VLOOKUP(B12,Planilha1!A:E,3,0) -> 20-A | G12: =VLOOKUP(B12,Planilha1!A:E,4,0) -> 30 | H12: * | I12: * | J12: * | K12: MERITOR BR - FABRICA OSASCO | L12: =VLOOKUP(B12,Planilha1!A:E,5,0) -> TUBO RADIANTE EM ACO REFRATARIO P/FORNO AICHELIN TIPO KSES - 2 ITENS 732 E 736. (ESTRATEGICO PARA MANUTENCAO).(PEDIDO EM ABERTO CINDAX).
A13: OSR | B13: M410001357 | C13: 71MG51ALM | E13: EA | F13: =VLOOKUP(B13,Planilha1!A:E,3,0) -> 5E-5A2 | G13: =VLOOKUP(B13,Planilha1!A:E,4,0) -> 150 | H13: * | I13: * | J13: * | K13: MERITOR BR - FABRICA OSASCO | L13: =VLOOKUP(B13,Planilha1!A:E,5,0) -> TUBO DE CONTATO M10 1
A14: OSR | B14: M490140000 | C14: 71MG51ALM | E14: EA | F14: =VLOOKUP(B14,Planilha1!A:E,3,0) -> 14B-7B | G14: =VLOOKUP(B14,Planilha1!A:E,4,0) -> 1 | H14: * | I14: * | J14: * | K14: MERITOR BR - FABRICA OSASCO | L14: =VLOOKUP(B14,Planilha1!A:E,5,0) -> PRE-FILTRO CODIGO 4-9710-136 (PEDIDO EM ABERTO DELLBRO).
... A28: OSR | B28: M350003092 | C28: 71MG51ALM | E28: EA | F28: =VLOOKUP(B28,Planilha1!A:E,3,0) -> INFLAMAVEL-27 | G28: =VLOOKUP(B28,Planilha1!A:E,4,0) -> 19 | H28: * | I28: * | J28: * | K28: MERITOR BR - FABRICA OSASCO | L28: =VLOOKUP(B28,Planilha1!A:E,5,0) -> THINNER NATRIELLI 8100 (EMBALAGEM C/ 6 LITROS - PRODUTO QUIMICO). (CONTA CORRETA 95483). (LOTE MINIMO-42 LATAS). (PEDIDO EM ABERTO NATRIELLI QUIMICA).

Sheet Planilha1
A1: Item | B1: Subinventory | C1: Locator | D1: On-hand Qty | E1: Item Description
A2: M190000424 | B2: 71MG51ALM | C2: 8B-8C2 | D2: 2 | E2: BROCA DIA. 10.5X125MM HASTE DE 14MM
A3: M000000050 | B3: 71MG51ALM | C3: 2G-2B | D3: 2 | E3: CONJUNTO DA CORRENTE DE ELEVACAO TORRA PADRAO COD. 90630U709571 - LEAD TIME 20 DIAS
A4: M000000069 | B4: 71MG51ALM | C4: 19J-3 | D4: 1 | E4: DOUBLE ROW TAPERED ROLLER BEARING WITH SPACER. (MACHTOOLS). (ESTRATEGICO PARA MANUTENCAO).
A5: M000000149 | B5: 71MG51ALM | C5: 5F-3C2 | D5: 10 | E5: BACK PARA SOLDA LONGITUDINAL K-04364 DETALHE 22. (PEDIDO EM ABERTO LEMOR).
A6: M000000151 | B6: 71MG51ALM | C6: 5F-3C1 | D6: 8 | E6: BACK PARA SOLDA LONGITUDINAL K-04364 DETALHE 23. (PEDIDO EM ABERTO LEMOR).
A7: M000000164 | B7: 71MG51ALM | C7: 1E-5D2 | D7: 1 | E7: EE-003882-000 - CABO DO SENSOR DE TRINCA - LEAD TIME 30 DIAS
A8: M000000206 | B8: 71MG51ALM | C8: 5D-3E3 | D8: 6 | E8: GATILHO 2-POLOS
A9: M000000207 | B9: 71MG51ALM | C9: 1E-5D1 | D9: 1 | E9: EE-003606-000 - SENSOR ACUSTICO - LEAD TIME 30 DIAS
A10: M000000214 | B10: 71MG51ALM | C10: 1F-6C4 | D10: 8 | E10: SOQUETE SEXTAVADO 1/2 X 1/2 REFERENCIA 19 CODIGO 015055 - GEDORE (JSA/CELMAR/FRATO). (PEDIDO EM ABERTO CRA).
A11: M000000243 | B11: 71MG51ALM | C11: 1F-14E | D11: 6 | E11: 1090024 - SAP2-10 SUPORTE EM ALUMINIO P/10 PASTAS A4R/A3P - LEAD TIME 3 DIAS
A12: M000000263 | B12: 71MG51ALM | C12: 13E-4A | D12: 48 | E12: 1030007 PIA4R-AZ - PASTA ISOFLEX A4 RETRATO AZUL - LEAD TIME 3 DIAS
A13: M000000264 | B13: 71MG51ALM | C13: 1F-12D | D13: 5 | E13: 1090005 - SIP1-05 SUPORTE EM ABS ISOFLEX PARA PASTAS A4R/A3 - LEAD TIME 3 DIAS
... A330: M000181366 | B330: 71MG51ALM | C330: 19H-4 | D330: 1 | E330: REBOLO 18-0051 ZEMA OE-091F-003 - LEAD TIME 90 DIAS
A331: M000181367 | B331: 71MG51ALM | C331: 1.9 | D331: 4 | E331: REBOLO 18-0052 ZEMA OE-091F-004 e 18-0053 ZEMA OE-091F-005 - LEAD TIME 90 DIAS
A332: M000181369 | B332: 71MG51ALM | C332: 19G-3 | D332: 2 | E332: REBOLO 18-0054 ZEMA OE-091F-006 E 18-0055 ZEMA OE-091F-007 - LEAD TIME 90 DIAS
A333: M000181371 | B333: 71MG51ALM | C333: 19L-3 | D333: 2 | E333: REBOLO 18-0056 ZEMA OE-091F-008 e 18-0057 ZEMA OE-091F-009 - LEAD TIME 90 DIAS
A334: M000181373 | B334: 71MG51ALM | C334: 19C-1 | D334: 4 | E334: REBOLO 18-0058 ZEMA OE-091F-010 e 18-0059 ZEMA OE-091F-011 - LEAD TIME 90 DIAS
A335: M000182314 | B335: 71MG51ALM | C335: 19F-3 | D335: 9 | E335: REBOLO DES. 18-2314 (PEDIDO EM ABERTO ALCAR) - LEAD TIME 60 DIAS
A336: M000182385 | B336: 71MG51ALM | C336: 19G-4 | D336: 2 | E336: REBOLO DES. 18-2385 (ALCAR) LEAD TIME 50 DIAS.
A337: M000182396 | B337: 71MG51ALM | C337: 0.19 | D337: 1 | E337: REBOLO ESPECIAL DES. 18-2396 REVISAO "A" - ESPECIFICACAO DA 54.3 K 8 V1CP (JOGO COM DUAS PECAS SENDO: 1 PECA ES 779
A338: M000182397 | B338: 71MG51ALM | C338: 19D-3 | D338: 2 | E338: REBOLO DES. 18-2397 REVISAO B
A339: M000183007 | B339: 71MG51ALM | C339: 14C-3B | D339: 4 | E339: REBOLO 152X 38X 31 DES.18-3007 AA80KSV TIPO CC REVISAO "H" (NORTON
A340: M000183010 | B340: 71MG51ALM | C340: 14C-3A | D340: 23 | E340: REBOLO DES. 18-3010 REVISAO E. (PEDIDO EM ABERTO ABRASAO).
A341: M000184070 | B341: 71MG51ALM | C341: 19L-4 | D341: 2 | E341: REBOLO DES. 18-4070 REVISAO "C" - LEAD TIME 60 DIAS - (CARBORUNDUM
A342: M000184071 | B342: 71MG51ALM | C342: 19H-3 | D342: 4 | E342: REBOLO DES. 18-4071. (CONJUNTO COMPOSTO POR DUAS PECAS). (PEDIDO EM ABERTO ALCAR) - LEAD TIME 60 DIAS
A343: M000184112 | B343: 71MG51ALM | C343: 19G-2 | D343: 1 | E343: REBOLO DES. 18-4112 S/REVIS O (PEDIDO EM ABERTO ALCAR) LEAD TIME 50 DIAS.
A344: M000187003 | B344: 71MG51ALM | C344: 9D-8F2 | D344: 5 | E344: PEDRA K-20 NM-49 DES.18-7003. (PEDIDO EM ABERTO SUNNEN).
A345: M000187004 | B345: 71MG51ALM | C345: 9C-3A1 | D345: 7 | E345: PEDRA R-28 NM-37 DES.18-7004. (PEDIDO EM ABERTO SUNNEN).
A346: M000187005 | B346: 71MG51ALM | C346: 9C-6A1 | D346: 8 | E346: PEDRA R-28 NM-05 DES.18-7005. (PEDIDO EM ABERTO SUNNEN).
A347: M000188001 | B347: 71MG51ALM | C347: 14C-5D | D347: 3 | E347: DISCO DE CORTE DIAMANTADO PARA METAL DURO DESENHO 18-8001. (APOLLO ABRASIVOS).
A348: M000188002 | B348: 71MG51ALM | C348: 1G-6A1 | D348: 5 | E348: DISCO DE CORTE DE METAIS/ACOS - INOX - 115MM X 1
A349: M000303029 | B349: 71MG51ALM | C349: 7C-7C2 | D349: 2 | E349: BROCA MD ESC. 14.50 X 25
... A1077: M090225250 | B1077: 71MG51ALM | C1077: 19P-2B | D1077: 130 | E1077: SACO PLASTICO TRANSPARENTE 220 X 320 X 0
A1078: M095010122 | B1078: 71MG51ALM | C1078: 16A-1AB | D1078: 27.4 | E1078: SACO PLASTICO TRANSPARENTE 150X250X0
A1079: M095010123 | B1079: 71MG51ALM | C1079: 19O-2B | D1079: 165 | E1079: SACO PLASTICO EM POLIETILENO 0
A1080: M095105153 | B1080: 71MG51ALM | C1080: 19L-2 | D1080: 31580 | E1080: SACOS PEBD TRANSPARENTE COM CORDOANEL 20X30 +3 X 0
A1081: M095150250 | B1081: 71MG51ALM | C1081: 19Q-1B | D1081: 195 | E1081: SACO PLASTICO TRANSPARENTE 150 X 250 X 0
A1082: M095840022 | B1082: 71MG51ALM | C1082: 14A-1B | D1082: 1900 | E1082: SACO DE POLIPROPILENO 215X 303 MM C/ TARJA BRANCA LATERAL E 11 FUROS UNIVERSAL. (CONTA CORRETA 95422 / 95423). (PEDIDO EM ABERTO ENVPLAS)
A1083: M097001520 | B1083: 71MG51ALM | C1083: 14A-5D | D1083: 84 | E1083: EXPOSITOR PVC LAMINADO PRETO COM VISOR EM PVC CRISTAL E ILHOS PARA PENDURAR COM ABA DE PROTECAO FORMATO 240 X 335 MM CODIGO 11506440. (PEDIDO EM ABERTO GIMBA).
...
